Workbook
Name EmpList: '00_Employees'!$B$3:$B$100

Sheet 00_Cover
B2: HOMEOCENTRUM — MODULE REGISTER WITH EMPLOYEE + LAYER STATUS (LIVE SYNC)
B3: 1000 sub-tasks · edit yellow cells on M00–M19 · Frontend/Backend/Database/API/Mobile/Integration each has Scope + Status + Assigned · Master and Dashboard follow automatically
B5: How to work this file (employees + layer status + sync)
B6: 1. Put real names on 00_Employees (yellow Name column). Keep “Unassigned”. Dropdowns on module sheets use those names.
B7: 2. EDIT on the module sheet (M05_Appointments, M17_Patient_Mobile, …). Yellow cells: Assigned To (lead), each function’s Status, each function’s Assigned, Notes.
B8: 3. Frontend / Backend / Database / API / Mobile / Integration: Scope Yes = this sub-task includes that work. Status N/A = not in this sub-task (Scope No). Status Not Started / In Progress / Done = remaining vs complete.
B9: 4. Change Frontend Status (or any layer Status) on the module sheet. 01_MASTER, 03_Web, 04_UI, 05_Mobile, 06_QA, 02_By_Module_Phase and 08_Dashboard update immediately (Excel formulas — no copy-paste).
B10: 5. Overall Status is calculated: all in-scope layers Done → Done; any Blocked → Blocked; any started but not all Done → In Progress; else Not Started. Do not type over Overall Status.
B11: 6. Layers Remaining = how many in-scope functions are not Done yet. Filter that column to see what is left in the module.
B12: 7. Same Sub Task ID is one row of work. Assign a lead plus a person per in-scope function (Frontend Assigned, API Assigned, …) when more than one employee works the row.
B13: 8. Do not type over Status on 01_MASTER or track sheets — those cells are live mirrors. Use “Open Module Sheet” to jump to the yellow editable row.
B14: 9. Develop sequentially inside a module (Web API → UI → Mobile → QA). Do not skip rows. Dashboard integrity must stay 1000.
... B17: Legend — function columns
B18: Yes | C18: Scope — this sub-task includes this function (Frontend/Backend/Database/API/Mobile/Integration).
B19: No | C19: Scope — not part of this sub-task. Status must stay N/A.
B20: Not Started | C20: In scope and remaining — not begun.
B21: In Progress | C21: In scope and remaining — someone is working it.
B22: Done | C22: In scope and complete.
B23: Blocked | C23: Cannot finish until a dependency or decision is cleared.
B24: N/A | C24: Not in scope for this row.
B25: Yellow cell | C25: Editable on the MODULE sheet only (assignment + layer Status).
B28: Modules — open the sheet named here to assign people and mark layer Status
B29: Code | C29: Dev Module | D29: Edit sheet | E29: Sub tasks | F29: Web | G29: UI | H29: Mobile | I29: QA
B30: M00 | C30: PRE — Client gates | D30: M00_PRE_Client_Gates | E30: 11 | F30: 11 | G30: 0 | H30: 0 | I30: 0
B31: M01 | C31: Foundation & Security | D31: M01_Foundation_Security | E31: 41 | F31: 24 | G31: 6 | H31: 1 | I31: 10
B32: M02 | C32: Admin clinical masters | D32: M02_Admin_Clinical | E32: 85 | F32: 56 | G32: 1 | H32: 0 | I32: 28
B33: M03 | C33: Doctor clinical workspace | D33: M03_Clinical_Workspace | E33: 67 | F33: 37 | G33: 10 | H33: 0 | I33: 20
B34: M04 | C34: Doctor daily operations | D34: M04_Doctor_Daily_Ops | E34: 33 | F34: 18 | G34: 5 | H34: 0 | I34: 10
B35: M05 | C35: Appointments & scheduling | D35: M05_Appointments | E35: 40 | F35: 23 | G35: 6 | H35: 0 | I35: 11
B36: M06 | C36: Reception portal | D36: M06_Reception | E36: 39 | F36: 18 | G36: 9 | H36: 0 | I36: 12
B37: M07 | C37: Payment system | D37: M07_Payments | E37: 42 | F37: 23 | G37: 8 | H37: 0 | I37: 11
B38: M08 | C38: Account & finance | D38: M08_Account_Finance | E38: 44 | F38: 22 | G38: 10 | H38: 0 | I38: 12
B39: M09 | C39: Trust & verification | D39: M09_Trust | E39: 27 | F39: 14 | G39: 6 | H39: 0 | I39: 7
B40: M10 | C40: Patient website | D40: M10_Patient_Website | E40: 35 | F40: 12 | G40: 12 | H40: 0 | I40: 11
B41: M11 | C41: Digital prescription (eRx) | D41: M11_Digital_eRx | E41: 35 | F41: 17 | G41: 8 | H41: 0 | I41: 10
... B49: M19 | C49: Reports, NFR & delivery gate | D49: M19_Reports_NFR_Gate | E49: 44 | F49: 18 | G49: 9 | H49: 0 | I49: 17

Sheet 00_Employees
A1: EMPLOYEES — type real names in column B (yellow). Keep row 3 as Unassigned. Google Sheets: open 00_Sheets_Dropdown once and connect the dropdowns. After that, a new name in column B appears on every module sheet by itself.
A2: Emp ID | B2: Name (shows in Assigned dropdowns) | C2: Function | D2: Track | E2: Active
A3: UNASSIGNED | B3: Unassigned | C3: Any | D3: Any | E3: Yes
A4: E01 | B4: Gourav Nikam | C4: Frontend | D4: UI | E4: Yes
A5: E02 | B5: Digvijay Jadhav | C5: Frontend | D5: UI | E5: Yes
A6: E03 | B6: Gourav Nikam | C6: Backend | D6: Web | E6: Yes
A7: E04 | C7: Backend | D7: Web | E7: Yes
A8: E05 | B8: Gourav Nikam | C8: Database | D8: Web | E8: Yes
A9: E06 | B9: Gourav Nikam | C9: API | D9: Web | E9: Yes
A10: E07 | C10: API | D10: Web | E10: Yes
A11: E08 | B11: Pranav Bandekar | C11: Mobile | D11: Mobile | E11: Yes
A12: E09 | C12: Mobile | D12: Mobile | E12: Yes
A13: E10 | B13: Gourav Nikam | C13: Integration | D13: Web | E13: Yes
A14: E11 | C14: QA | D14: QA | E14: Yes
A15: E12 | C15: QA | D15: QA | E15: Yes
A16: E13 | B16: Gourav Nikam | C16: Tech Lead | D16: Any | E16: Yes
E17: Yes
E18: Yes
E19: Yes
E20: Yes
E21: Yes
E22: Yes
E23: Yes
E24: Yes
E25: Yes
E26: Yes
E27: Yes
E28: Yes
... E100: Yes

Sheet 00_Sheets_Dropdown
A1: GOOGLE SHEETS — make Assigned To grow when you type a name in 00_Employees column B
A3: Excel cannot do this after you upload to Google Sheets. Do this once in Google Sheets. After that, new names in column B appear by themselves.
A4: 1. This file must be open in Google Sheets (File → Import → Replace, or upload to Drive and open with Sheets).
A5: 2. Menu: Extensions → Apps Script.
A6: 3. Delete any code in Code.gs. Copy ALL of the script in cell A20 below. Paste it. Click Save (disk icon).
A7: 4. Function dropdown: choose setupAssignedDropdowns. Click Run. Click Allow / Review permissions for your Google account.
A8: 5. Reload this spreadsheet. You should see a Homeocentrum menu. You can also use Homeocentrum → Connect Assigned dropdowns to Employees.
A9: 6. Go to 00_Employees. Type a real name in a yellow cell in column B. Open M05_Appointments. Click Assigned To (lead) — the new name is in the list. No second setup.
A10: Do not type Assigned names on Master. Edit on the module sheet. Keep row 3 as Unassigned.
A19: Copy everything in A20 (the script). Paste into Apps Script.
A20: /** * Homeocentrum — Assigned To dropdowns follow 00_Employees column B. * One-time setup in Google Sheets: * Extensions → Apps Script → paste this file → Save → Run setupAssignedDropdowns → Allow. * After that, type a new name in 00_Employees column B and it appears on every module sheet. */ function onOpen() { SpreadsheetApp.getUi() .createMenu("Homeocentrum") .addItem("Connect Assigned dropdowns to Employees", "setupAssignedDropdowns") .addToUi(); } function setupAssignedDropdowns() { var ss = SpreadsheetApp.getActive(); var emp = ss.getSheetByName("00_Employees"); if (!emp) { SpreadsheetApp.getUi().alert("Sheet 00_Employees was not found."); return; } var nameRange = emp.getRange("B3:B100"); var rule = SpreadsheetApp.newDataValidation() .requireValueInRange(nameRange, true) .setAllowInvalid(true) .setHelpText("Pick a name from 00_Employees column B. New names appear automatically.") .build(); var sheetsDone = 0; ss.getSheets().forEach(function (sh) { if (!/^M\d{2}_/.test(sh.getName())) return; var lastCol = Math.max(sh.getLastColumn(), 42); var headers = sh.getRange(2, 1, 1, lastCol).getValues()[0]; var lastRow = Math.max(sh.getLastRow(), 3); var height = lastRow - 2; if (height < 1) return; headers.forEach(function (h, i) { var title = String(h || ""); if (title === "Assigned To (lead)" || / Assigned$/.test(title)) { sh.getRange(3, i + 1, height, 1).setDataValidation(rule); } }); sheetsDone++; }); SpreadsheetApp.getUi().alert( "Done. Assigned To on " + sheetsDone + " module sheets now follows 00_Employees column B.\n\n" + "Type a new name in column B — it appears in the dropdown. You do not need to run this again." ); }

Sheet 01_MASTER
A1: MASTER MIRROR — do not type Status here. It is live from M00–M19. Click Open Module Sheet to assign an employee or mark Frontend/API/… Done. Filter to find work.
A2: Module Seq | B2: Original Seq | C2: Dev Module Code | D2: Dev Module | E2: Track | F2: Phase | G2: Phase Name | H2: WBS | I2: Main Task ID | J2: Main Task | K2: Sub Task ID | L2: Sub Task | M2: Work Type | N2: Source Module / Area | O2: PDF Section | P2: PDF Feature (exact wording) | Q2: PDF Delivery Text | R2: Application Surface | S2: Layer | T2: Assigned To (lead) | U2: Frontend | V2: Frontend Status | W2: Frontend Assigned | X2: Backend | Y2: Backend Status | Z2: Backend Assigned | AA2: Database | AB2: Database Status | AC2: Database Assigned | AD2: API | AE2: API Status | AF2: API Assigned | AG2: Mobile | AH2: Mobile Status | AI2: Mobile Assigned | AJ2: Integration | AK2: Integration Status | AL2: Integration Assigned | AM2: Layers Remaining | AN2: Overall Status | AO2: Notes | AP2: Open Module Sheet
A3: 1 | B3: 1 | C3: M00 | D3: PRE — Client gates | E3: Web | F3: PRE | G3: PRE — Client gates (must sign before Phase 6 money spine) | H3: PRE.1 | I3: PRE-01 | J3: Decide settlement model — Homeocentrum holds all money (food-delivery / quick-commerce pattern) | K3: PRE-01.01 | L3: Workshop with finance: confirm Homeocentrum is single merchant of record for consult + medicine + subscription | M3: Client Decision | N3: Finance | O3: §9 + §8 | P3: Every transaction passes through Homeocentrum | Q3: Built on the principle: every transaction passes through Homeocentrum, in the same way a food-delivery or quick-commerce platform holds all payments centrally. | R3: Account / Gateway | S3: Decision | T3: {=IFERROR(INDEX(INDIRECT("'"&VLOOKUP($C3,ModMap!$A$2:$B$21,2,FALSE)&"'!T:T"),MATCH($K3,INDIRECT("'"&VLOOKUP($C3,ModMap!$A$2:$B$21,2,FALSE)&"'!$K:$K"),0)),"")} -> Unassigned | U3: No | V3: {=IFERROR(INDEX(INDIRECT("'"&VLOOKUP($C3,ModMap!$A$2:$B$21,2,FALSE)&"'!V:V"),MATCH($K3,INDIRECT("'"&VLOOKUP($C3,ModMap!$A$2:$B$21,2,FALSE)&"'!$K:$K"),0)),"")} -> N/A | W3: {=IFERROR(INDEX(INDIRECT("'"&VLOOKUP($C3,ModMap!$A$2:$B$21,2,FALSE)&"'!W:W"),MATCH($K3,INDIRECT("'"&VLOOKUP($C3,ModMap!$A$2:$B$21,2,FALSE)&"'!$K:$K"),0)),"")} | X3: No | Y3: {=IFERROR(INDEX(INDIRECT("'"&VLOOKUP($C3,ModMap!$A$2:$B$21,2,FALSE)&"'!Y:Y"),MATCH($K3,INDIRECT("'"&VLOOKUP($C3,ModMap!$A$2:$B$21,2,FALSE)&"'!$K:$K"),0)),"")} -> N/A | Z3: {=IFERROR(INDEX(INDIRECT("'"&VLOOKUP($C3,ModMap!$A$2:$B$21,2,FALSE)&"'!Z:Z"),MATCH($K3,INDIRECT("'"&VLOOKUP($C3,ModMap!$A$2:$B$21,2,FALSE)&"'!$K:$K"),0)),"")} | AA3: No | AB3: {=IFERROR(INDEX(INDIRECT("'"&VLOOKUP($C3,ModMap!$A$2:$B$21,2,FALSE)&"'!AB:AB"),MATCH($K3,INDIRECT("'"&VLOOKUP($C3,ModMap!$A$2:$B$21,2,FALSE)&"'!$K:$K"),0)),"")} -> N/A | AC3: {=IFERROR(INDEX(INDIRECT("'"&VLOOKUP($C3,ModMap!$A$2:$B$21,2,FALSE)&"'!AC:AC"),MATCH($K3,INDIRECT("'"&VLOOKUP($C3,ModMap!$A$2:$B$21,2,FALSE)&"'!$K:$K"),0)),"")} | AD3: No | AE3: {=IFERROR(INDEX(INDIRECT("'"&VLOOKUP($C3,ModMap!$A$2:$B$21,2,FALSE)&"'!AE:AE"),MATCH($K3,INDIRECT("'"&VLOOKUP($C3,ModMap!$A$2:$B$21,2,FALSE)&"'!$K:$K"),0)),"")} -> N/A | AF3: {=IFERROR(INDEX(INDIRECT("'"&VLOOKUP($C3,ModMap!$A$2:$B$21,2,FALSE)&"'!AF:AF"),MATCH($K3,INDIRECT("'"&VLOOKUP($C3,ModMap!$A$2:$B$21,2,FALSE)&"'!$K:$K"),0)),"")} | AG3: No | AH3: {=IFERROR(INDEX(INDIRECT("'"&VLOOKUP($C3,ModMap!$A$2:$B$21,2,FALSE)&"'!AH:AH"),MATCH($K3,INDIRECT("'"&VLOOKUP($C3,ModMap!$A$2:$B$21,2,FALSE)&"'!$K:$K"),0)),"")} -> N/A | AI3: {=IFERROR(INDEX(INDIRECT("'"&VLOOKUP($C3,ModMap!$A$2:$B$21,2,FALSE)&"'!AI:AI"),MATCH($K3,INDIRECT("'"&VLOOKUP($C3,ModMap!$A$2:$B$21,2,FALSE)&"'!$K:$K"),0)),"")} | AJ3: No | AK3: {=IFERROR(INDEX(INDIRECT("'"&VLOOKUP($C3,ModMap!$A$2:$B$21,2,FALSE)&"'!AK:AK"),MATCH($K3,INDIRECT("'"&VLOOKUP($C3,ModMap!$A$2:$B$21,2,FALSE)&"'!$K:$K"),0)),"")} -> N/A | AL3: {=IFERROR(INDEX(INDIRECT("'"&VLOOKUP($C3,ModMap!$A$2:$B$21,2,FALSE)&"'!AL:AL"),MATCH($K3,INDIRECT("'"&VLOOKUP($C3,ModMap!$A$2:$B$21,2,FALSE)&"'!$K:$K"),0)),"")} | AM3: =IF(AND(U3="Yes",V3<>"Done",V3<>"Deferred",V3<>"N/A"),1,0)+IF(AND(X3="Yes",Y3<>"Done",Y3<>"Deferred",Y3<>"N/A"),1,0)+IF(AND(AA3="Yes",AB3<>"Done",AB3<>"Deferred",AB3<>"N/A"),1,0)+IF(AND(AD3="Yes",AE3<>"Done",AE3<>"Deferred",AE3<>"N/A"),1,0)+IF(AND(AG3="Yes",AH3<>"Done",AH3<>"Deferred",AH3<>"N/A"),1,0)+IF(AND(AJ3="Yes",AK3<>"Done",AK3<>"Deferred",AK3<>"N/A"),1,0) -> 0 | AN3: =IF((IF(U3="Yes",1,0)+IF(X3="Yes",1,0)+IF(AA3="Yes",1,0)+IF(AD3="Yes",1,0)+IF(AG3="Yes",1,0)+IF(AJ3="Yes",1,0))=0,"N/A",IF((IF(AND(U3="Yes",V3="Blocked"),1,0)+IF(AND(X3="Yes",Y3="Blocked"),1,0)+IF(AND(AA3="Yes",AB3="Blocked"),1,0)+IF(AND(AD3="Yes",AE3="Blocked"),1,0)+IF(AND(AG3="Yes",AH3="Blocked"),1,0)+IF(AND(AJ3="Yes",AK3="Blocked"),1,0))>0,"Blocked",IF((IF(AND(U3="Yes",V3="Done"),1,0)+IF(AND(X3="Yes",Y3="Done"),1,0)+IF(AND(AA3="Yes",AB3="Done"),1,0)+IF(AND(AD3="Yes",AE3="Done"),1,0)+IF(AND(AG3="Yes",AH3="Done"),1,0)+IF(AND(AJ3="Yes",AK3="Done"),1,0))=(IF(U3="Yes",1,0)+IF(X3="Yes",1,0)+IF(AA3="Yes",1,0)+IF(AD3="Yes",1,0)+IF(AG3="Yes",1,0)+IF(AJ3="Yes",1,0)),"Done",IF((IF(AND(U3="Yes",OR(V3="In Progress",V3="Done",V3="Deferred")),1,0)+IF(AND(X3="Yes",OR(Y3="In Progress",Y3="Done",Y3="Deferred")),1,0)+IF(AND(AA3="Yes",OR(AB3="In Progress",AB3="Done",AB3="Deferred")),1,0)+IF(AND(AD3="Yes",OR(AE3="In Progress",AE3="Done",AE3="Deferred")),1,0)+IF(AND(AG3="Yes",OR(AH3="In Progress",AH3="Done",AH3="Deferred")),1,0)+IF(AND(AJ3="Yes",OR(AK3="In Progress",AK3="Done",AK3="Deferred")),1,0))>0,"In Progress","Not Started")))) -> N/A | AO3: {=IFERROR(INDEX(INDIRECT("'"&VLOOKUP($C3,ModMap!$A$2:$B$21,2,FALSE)&"'!AO:AO"),MATCH($K3,INDIRECT("'"&VLOOKUP($C3,ModMap!$A$2:$B$21,2,FALSE)&"'!$K:$K"),0)),"")} | AP3: {=IFERROR(HYPERLINK("#'"&VLOOKUP($C3,ModMap!$A$2:$B$21,2,FALSE)&"'!V"&MATCH($K3,INDIRECT("'"&VLOOKUP($C3,ModMap!$A$2:$B$21,2,FALSE)&"'!$K:$K"),0),"Edit on module sheet"),"")} -> Edit on module sheet
A4: 2 | B4: 2 | C4: M00 | D4: PRE — Client gates | E4: Web | F4: PRE | G4: PRE — Client gates (must sign before Phase 6 money spine) | H4: PRE.1 | I4: PRE-01 | J4: Decide settlement model — Homeocentrum holds all money (food-delivery / quick-commerce pattern) | K4: PRE-01.02 | L4: Choose v1 payout mechanic: Homeocentrum-held + NEFT/IMPS vs Razorpay Route / linked accounts | M4: Client Decision | N4: Finance | O4: §9 + §8 | P4: Every transaction passes through Homeocentrum | Q4: Built on the principle: every transaction passes through Homeocentrum, in the same way a food-delivery or quick-commerce platform holds all payments centrally. | R4: Account / Gateway | S4: Decision | T4: {=IFERROR(INDEX(INDIRECT("'"&VLOOKUP($C4,ModMap!$A$2:$B$21,2,FALSE)&"'!T:T"),MATCH($K4,INDIRECT("'"&VLOOKUP($C4,ModMap!$A$2:$B$21,2,FALSE)&"'!$K:$K"),0)),"")} -> Unassigned | U4: No | V4: {=IFERROR(INDEX(INDIRECT("'"&VLOOKUP($C4,ModMap!$A$2:$B$21,2,FALSE)&"'!V:V"),MATCH($K4,INDIRECT("'"&VLOOKUP($C4,ModMap!$A$2:$B$21,2,FALSE)&"'!$K:$K"),0)),"")} -> N/A | W4: {=IFERROR(INDEX(INDIRECT("'"&VLOOKUP($C4,ModMap!$A$2:$B$21,2,FALSE)&"'!W:W"),MATCH($K4,INDIRECT("'"&VLOOKUP($C4,ModMap!$A$2:$B$21,2,FALSE)&"'!$K:$K"),0)),"")} | X4: No | Y4: {=IFERROR(INDEX(INDIRECT("'"&VLOOKUP($C4,ModMap!$A$2:$B$21,2,FALSE)&"'!Y:Y"),MATCH($K4,INDIRECT("'"&VLOOKUP($C4,ModMap!$A$2:$B$21,2,FALSE)&"'!$K:$K"),0)),"")} -> N/A | Z4: {=IFERROR(INDEX(INDIRECT("'"&VLOOKUP($C4,ModMap!$A$2:$B$21,2,FALSE)&"'!Z:Z"),MATCH($K4,INDIRECT("'"&VLOOKUP($C4,ModMap!$A$2:$B$21,2,FALSE)&"'!$K:$K"),0)),"")} | AA4: No | AB4: {=IFERROR(INDEX(INDIRECT("'"&VLOOKUP($C4,ModMap!$A$2:$B$21,2,FALSE)&"'!AB:AB"),MATCH($K4,INDIRECT("'"&VLOOKUP($C4,ModMap!$A$2:$B$21,2,FALSE)&"'!$K:$K"),0)),"")} -> N/A | AC4: {=IFERROR(INDEX(INDIRECT("'"&VLOOKUP($C4,ModMap!$A$2:$B$21,2,FALSE)&"'!AC:AC"),MATCH($K4,INDIRECT("'"&VLOOKUP($C4,ModMap!$A$2:$B$21,2,FALSE)&"'!$K:$K"),0)),"")} | AD4: No | AE4: {=IFERROR(INDEX(INDIRECT("'"&VLOOKUP($C4,ModMap!$A$2:$B$21,2,FALSE)&"'!AE:AE"),MATCH($K4,INDIRECT("'"&VLOOKUP($C4,ModMap!$A$2:$B$21,2,FALSE)&"'!$K:$K"),0)),"")} -> N/A | AF4: {=IFERROR(INDEX(INDIRECT("'"&VLOOKUP($C4,ModMap!$A$2:$B$21,2,FALSE)&"'!AF:AF"),MATCH($K4,INDIRECT("'"&VLOOKUP($C4,ModMap!$A$2:$B$21,2,FALSE)&"'!$K:$K"),0)),"")} | AG4: No | AH4: {=IFERROR(INDEX(INDIRECT("'"&VLOOKUP($C4,ModMap!$A$2:$B$21,2,FALSE)&"'!AH:AH"),MATCH($K4,INDIRECT("'"&VLOOKUP($C4,ModMap!$A$2:$B$21,2,FALSE)&"'!$K:$K"),0)),"")} -> N/A | AI4: {=IFERROR(INDEX(INDIRECT("'"&VLOOKUP($C4,ModMap!$A$2:$B$21,2,FALSE)&"'!AI:AI"),MATCH($K4,INDIRECT("'"&VLOOKUP($C4,ModMap!$A$2:$B$21,2,FALSE)&"'!$K:$K"),0)),"")} | AJ4: Yes | AK4: {=IFERROR(INDEX(INDIRECT("'"&VLOOKUP($C4,ModMap!$A$2:$B$21,2,FALSE)&"'!AK:AK"),MATCH($K4,INDIRECT("'"&VLOOKUP($C4,ModMap!$A$2:$B$21,2,FALSE)&"'!$K:$K"),0)),"")} -> Not Started | AL4: {=IFERROR(INDEX(INDIRECT("'"&VLOOKUP($C4,ModMap!$A$2:$B$21,2,FALSE)&"'!AL:AL"),MATCH($K4,INDIRECT("'"&VLOOKUP($C4,ModMap!$A$2:$B$21,2,FALSE)&"'!$K:$K"),0)),"")} -> Unassigned | AM4: =IF(AND(U4="Yes",V4<>"Done",V4<>"Deferred",V4<>"N/A"),1,0)+IF(AND(X4="Yes",Y4<>"Done",Y4<>"Deferred",Y4<>"N/A"),1,0)+IF(AND(AA4="Yes",AB4<>"Done",AB4<>"Deferred",AB4<>"N/A"),1,0)+IF(AND(AD4="Yes",AE4<>"Done",AE4<>"Deferred",AE4<>"N/A"),1,0)+IF(AND(AG4="Yes",AH4<>"Done",AH4<>"Deferred",AH4<>"N/A"),1,0)+IF(AND(AJ4="Yes",AK4<>"Done",AK4<>"Deferred",AK4<>"N/A"),1,0) -> 1 | AN4: =IF((IF(U4="Yes",1,0)+IF(X4="Yes",1,0)+IF(AA4="Yes",1,0)+IF(AD4="Yes",1,0)+IF(AG4="Yes",1,0)+IF(AJ4="Yes",1,0))=0,"N/A",IF((IF(AND(U4="Yes",V4="Blocked"),1,0)+IF(AND(X4="Yes",Y4="Blocked"),1,0)+IF(AND(AA4="Yes",AB4="Blocked"),1,0)+IF(AND(AD4="Yes",AE4="Blocked"),1,0)+IF(AND(AG4="Yes",AH4="Blocked"),1,0)+IF(AND(AJ4="Yes",AK4="Blocked"),1,0))>0,"Blocked",IF((IF(AND(U4="Yes",V4="Done"),1,0)+IF(AND(X4="Yes",Y4="Done"),1,0)+IF(AND(AA4="Yes",AB4="Done"),1,0)+IF(AND(AD4="Yes",AE4="Done"),1,0)+IF(AND(AG4="Yes",AH4="Done"),1,0)+IF(AND(AJ4="Yes",AK4="Done"),1,0))=(IF(U4="Yes",1,0)+IF(X4="Yes",1,0)+IF(AA4="Yes",1,0)+IF(AD4="Yes",1,0)+IF(AG4="Yes",1,0)+IF(AJ4="Yes",1,0)),"Done",IF((IF(AND(U4="Yes",OR(V4="In Progress",V4="Done",V4="Deferred")),1,0)+IF(AND(X4="Yes",OR(Y4="In Progress",Y4="Done",Y4="Deferred")),1,0)+IF(AND(AA4="Yes",OR(AB4="In Progress",AB4="Done",AB4="Deferred")),1,0)+IF(AND(AD4="Yes",OR(AE4="In Progress",AE4="Done",AE4="Deferred")),1,0)+IF(AND(AG4="Yes",OR(AH4="In Progress",AH4="Done",AH4="Deferred")),1,0)+IF(AND(AJ4="Yes",OR(AK4="In Progress",AK4="Done",AK4="Deferred")),1,0))>0,"In Progress","Not Started")))) -> Not Started | AO4: {=IFERROR(INDEX(INDIRECT("'"&VLOOKUP($C4,ModMap!$A$2:$B$21,2,FALSE)&"'!AO:AO"),MATCH($K4,INDIRECT("'"&VLOOKUP($C4,ModMap!$A$2:$B$21,2,FALSE)&"'!$K:$K"),0)),"")} | AP4: {=IFERROR(HYPERLINK("#'"&VLOOKUP($C4,ModMap!$A$2:$B$21,2,FALSE)&"'!V"&MATCH($K4,INDIRECT("'"&VLOOKUP($C4,ModMap!$A$2:$B$21,2,FALSE)&"'!$K:$K"),0),"Edit on module sheet"),"")} -> Edit on module sheet
A5: 3 | B5: 3 | C5: M00 | D5: PRE — Client gates | E5: Web | F5: PRE | G5: PRE — Client gates (must sign before Phase 6 money spine) | H5: PRE.1 | I5: PRE-01 | J5: Decide settlement model — Homeocentrum holds all money (food-delivery / quick-commerce pattern) | K5: PRE-01.03 | L5: Record decision in config (SettlementModel) — engineering must not hardcode a split model | M5: Configuration | N5: Finance | O5: §9 + §8 | P5: Every transaction passes through Homeocentrum | Q5: Built on the principle: every transaction passes through Homeocentrum, in the same way a food-delivery or quick-commerce platform holds all payments centrally. | R5: Account / Gateway | S5: Configuration | T5: {=IFERROR(INDEX(INDIRECT("'"&VLOOKUP($C5,ModMap!$A$2:$B$21,2,FALSE)&"'!T:T"),MATCH($K5,INDIRECT("'"&VLOOKUP($C5,ModMap!$A$2:$B$21,2,FALSE)&"'!$K:$K"),0)),"")} -> Unassigned | U5: No | V5: {=IFERROR(INDEX(INDIRECT("'"&VLOOKUP($C5,ModMap!$A$2:$B$21,2,FALSE)&"'!V:V"),MATCH($K5,INDIRECT("'"&VLOOKUP($C5,ModMap!$A$2:$B$21,2,FALSE)&"'!$K:$K"),0)),"")} -> N/A | W5: {=IFERROR(INDEX(INDIRECT("'"&VLOOKUP($C5,ModMap!$A$2:$B$21,2,FALSE)&"'!W:W"),MATCH($K5,INDIRECT("'"&VLOOKUP($C5,ModMap!$A$2:$B$21,2,FALSE)&"'!$K:$K"),0)),"")} | X5: Yes | Y5: {=IFERROR(INDEX(INDIRECT("'"&VLOOKUP($C5,ModMap!$A$2:$B$21,2,FALSE)&"'!Y:Y"),MATCH($K5,INDIRECT("'"&VLOOKUP($C5,ModMap!$A$2:$B$21,2,FALSE)&"'!$K:$K"),0)),"")} -> Not Started | Z5: {=IFERROR(INDEX(INDIRECT("'"&VLOOKUP($C5,ModMap!$A$2:$B$21,2,FALSE)&"'!Z:Z"),MATCH($K5,INDIRECT("'"&VLOOKUP($C5,ModMap!$A$2:$B$21,2,FALSE)&"'!$K:$K"),0)),"")} -> Unassigned | AA5: No | AB5: {=IFERROR(INDEX(INDIRECT("'"&VLOOKUP($C5,ModMap!$A$2:$B$21,2,FALSE)&"'!AB:AB"),MATCH($K5,INDIRECT("'"&VLOOKUP($C5,ModMap!$A$2:$B$21,2,FALSE)&"'!$K:$K"),0)),"")} -> N/A | AC5: {=IFERROR(INDEX(INDIRECT("'"&VLOOKUP($C5,ModMap!$A$2:$B$21,2,FALSE)&"'!AC:AC"),MATCH($K5,INDIRECT("'"&VLOOKUP($C5,ModMap!$A$2:$B$21,2,FALSE)&"'!$K:$K"),0)),"")} | AD5: No | AE5: {=IFERROR(INDEX(INDIRECT("'"&VLOOKUP($C5,ModMap!$A$2:$B$21,2,FALSE)&"'!AE:AE"),MATCH($K5,INDIRECT("'"&VLOOKUP($C5,ModMap!$A$2:$B$21,2,FALSE)&"'!$K:$K"),0)),"")} -> N/A | AF5: {=IFERROR(INDEX(INDIRECT("'"&VLOOKUP($C5,ModMap!$A$2:$B$21,2,FALSE)&"'!AF:AF"),MATCH($K5,INDIRECT("'"&VLOOKUP($C5,ModMap!$A$2:$B$21,2,FALSE)&"'!$K:$K"),0)),"")} | AG5: No | AH5: {=IFERROR(INDEX(INDIRECT("'"&VLOOKUP($C5,ModMap!$A$2:$B$21,2,FALSE)&"'!AH:AH"),MATCH($K5,INDIRECT("'"&VLOOKUP($C5,ModMap!$A$2:$B$21,2,FALSE)&"'!$K:$K"),0)),"")} -> N/A | AI5: {=IFERROR(INDEX(INDIRECT("'"&VLOOKUP($C5,ModMap!$A$2:$B$21,2,FALSE)&"'!AI:AI"),MATCH($K5,INDIRECT("'"&VLOOKUP($C5,ModMap!$A$2:$B$21,2,FALSE)&"'!$K:$K"),0)),"")} | AJ5: No | AK5: {=IFERROR(INDEX(INDIRECT("'"&VLOOKUP($C5,ModMap!$A$2:$B$21,2,FALSE)&"'!AK:AK"),MATCH($K5,INDIRECT("'"&VLOOKUP($C5,ModMap!$A$2:$B$21,2,FALSE)&"'!$K:$K"),0)),"")} -> N/A | AL5: {=IFERROR(INDEX(INDIRECT("'"&VLOOKUP($C5,ModMap!$A$2:$B$21,2,FALSE)&"'!AL:AL"),MATCH($K5,INDIRECT("'"&VLOOKUP($C5,ModMap!$A$2:$B$21,2,FALSE)&"'!$K:$K"),0)),"")} | AM5: =IF(AND(U5="Yes",V5<>"Done",V5<>"Deferred",V5<>"N/A"),1,0)+IF(AND(X5="Yes",Y5<>"Done",Y5<>"Deferred",Y5<>"N/A"),1,0)+IF(AND(AA5="Yes",AB5<>"Done",AB5<>"Deferred",AB5<>"N/A"),1,0)+IF(AND(AD5="Yes",AE5<>"Done",AE5<>"Deferred",AE5<>"N/A"),1,0)+IF(AND(AG5="Yes",AH5<>"Done",AH5<>"Deferred",AH5<>"N/A"),1,0)+IF(AND(AJ5="Yes",AK5<>"Done",AK5<>"Deferred",AK5<>"N/A"),1,0) -> 1 | AN5: =IF((IF(U5="Yes",1,0)+IF(X5="Yes",1,0)+IF(AA5="Yes",1,0)+IF(AD5="Yes",1,0)+IF(AG5="Yes",1,0)+IF(AJ5="Yes",1,0))=0,"N/A",IF((IF(AND(U5="Yes",V5="Blocked"),1,0)+IF(AND(X5="Yes",Y5="Blocked"),1,0)+IF(AND(AA5="Yes",AB5="Blocked"),1,0)+IF(AND(AD5="Yes",AE5="Blocked"),1,0)+IF(AND(AG5="Yes",AH5="Blocked"),1,0)+IF(AND(AJ5="Yes",AK5="Blocked"),1,0))>0,"Blocked",IF((IF(AND(U5="Yes",V5="Done"),1,0)+IF(AND(X5="Yes",Y5="Done"),1,0)+IF(AND(AA5="Yes",AB5="Done"),1,0)+IF(AND(AD5="Yes",AE5="Done"),1,0)+IF(AND(AG5="Yes",AH5="Done"),1,0)+IF(AND(AJ5="Yes",AK5="Done"),1,0))=(IF(U5="Yes",1,0)+IF(X5="Yes",1,0)+IF(AA5="Yes",1,0)+IF(AD5="Yes",1,0)+IF(AG5="Yes",1,0)+IF(AJ5="Yes",1,0)),"Done",IF((IF(AND(U5="Yes",OR(V5="In Progress",V5="Done",V5="Deferred")),1,0)+IF(AND(X5="Yes",OR(Y5="In Progress",Y5="Done",Y5="Deferred")),1,0)+IF(AND(AA5="Yes",OR(AB5="In Progress",AB5="Done",AB5="Deferred")),1,0)+IF(AND(AD5="Yes",OR(AE5="In Progress",AE5="Done",AE5="Deferred")),1,0)+IF(AND(AG5="Yes",OR(AH5="In Progress",AH5="Done",AH5="Deferred")),1,0)+IF(AND(AJ5="Yes",OR(AK5="In Progress",AK5="Done",AK5="Deferred")),1,0))>0,"In Progress","Not Started")))) -> Not Started | AO5: {=IFERROR(INDEX(INDIRECT("'"&VLOOKUP($C5,ModMap!$A$2:$B$21,2,FALSE)&"'!AO:AO"),MATCH($K5,INDIRECT("'"&VLOOKUP($C5,ModMap!$A$2:$B$21,2,FALSE)&"'!$K:$K"),0)),"")} | AP5: {=IFERROR(HYPERLINK("#'"&VLOOKUP($C5,ModMap!$A$2:$B$21,2,FALSE)&"'!V"&MATCH($K5,INDIRECT("'"&VLOOKUP($C5,ModMap!$A$2:$B$21,2,FALSE)&"'!$K:$K"),0),"Edit on module sheet"),"")} -> Edit on module sheet
A6: 4 | B6: 4 | C6: M00 | D6: PRE — Client gates | E6: Web | F6: PRE | G6: PRE — Client gates (must sign before Phase 6 money spine) | H6: PRE.2 | I6: PRE-02 | J6: Decide reception cash policy — clinic retains vs remits to Homeocentrum | K6: PRE-02.01 | L6: OQ: cash collected at reception retained by clinic or remitted to Homeocentrum? | M6: Client Decision | N6: Finance / Reception | O6: §9 | P6: Reception payment collection | Q6: Cash, UPI, card or payment link with printed receipt | R6: Account / Reception | S6: Decision | T6: {=IFERROR(INDEX(INDIRECT("'"&VLOOKUP($C6,ModMap!$A$2:$B$21,2,FALSE)&"'!T:T"),MATCH($K6,INDIRECT("'"&VLOOKUP($C6,ModMap!$A$2:$B$21,2,FALSE)&"'!$K:$K"),0)),"")} -> Unassigned | U6: No | V6: {=IFERROR(INDEX(INDIRECT("'"&VLOOKUP($C6,ModMap!$A$2:$B$21,2,FALSE)&"'!V:V"),MATCH($K6,INDIRECT("'"&VLOOKUP($C6,ModMap!$A$2:$B$21,2,FALSE)&"'!$K:$K"),0)),"")} -> N/A | W6: {=IFERROR(INDEX(INDIRECT("'"&VLOOKUP($C6,ModMap!$A$2:$B$21,2,FALSE)&"'!W:W"),MATCH($K6,INDIRECT("'"&VLOOKUP($C6,ModMap!$A$2:$B$21,2,FALSE)&"'!$K:$K"),0)),"")} | X6: No | Y6: {=IFERROR(INDEX(INDIRECT("'"&VLOOKUP($C6,ModMap!$A$2:$B$21,2,FALSE)&"'!Y:Y"),MATCH($K6,INDIRECT("'"&VLOOKUP($C6,ModMap!$A$2:$B$21,2,FALSE)&"'!$K:$K"),0)),"")} -> N/A | Z6: {=IFERROR(INDEX(INDIRECT("'"&VLOOKUP($C6,ModMap!$A$2:$B$21,2,FALSE)&"'!Z:Z"),MATCH($K6,INDIRECT("'"&VLOOKUP($C6,ModMap!$A$2:$B$21,2,FALSE)&"'!$K:$K"),0)),"")} | AA6: No | AB6: {=IFERROR(INDEX(INDIRECT("'"&VLOOKUP($C6,ModMap!$A$2:$B$21,2,FALSE)&"'!AB:AB"),MATCH($K6,INDIRECT("'"&VLOOKUP($C6,ModMap!$A$2:$B$21,2,FALSE)&"'!$K:$K"),0)),"")} -> N/A | AC6: {=IFERROR(INDEX(INDIRECT("'"&VLOOKUP($C6,ModMap!$A$2:$B$21,2,FALSE)&"'!AC:AC"),MATCH($K6,INDIRECT("'"&VLOOKUP($C6,ModMap!$A$2:$B$21,2,FALSE)&"'!$K:$K"),0)),"")} | AD6: No | AE6: {=IFERROR(INDEX(INDIRECT("'"&VLOOKUP($C6,ModMap!$A$2:$B$21,2,FALSE)&"'!AE:AE"),MATCH($K6,INDIRECT("'"&VLOOKUP($C6,ModMap!$A$2:$B$21,2,FALSE)&"'!$K:$K"),0)),"")} -> N/A | AF6: {=IFERROR(INDEX(INDIRECT("'"&VLOOKUP($C6,ModMap!$A$2:$B$21,2,FALSE)&"'!AF:AF"),MATCH($K6,INDIRECT("'"&VLOOKUP($C6,ModMap!$A$2:$B$21,2,FALSE)&"'!$K:$K"),0)),"")} | AG6: No | AH6: {=IFERROR(INDEX(INDIRECT("'"&VLOOKUP($C6,ModMap!$A$2:$B$21,2,FALSE)&"'!AH:AH"),MATCH($K6,INDIRECT("'"&VLOOKUP($C6,ModMap!$A$2:$B$21,2,FALSE)&"'!$K:$K"),0)),"")} -> N/A | AI6: {=IFERROR(INDEX(INDIRECT("'"&VLOOKUP($C6,ModMap!$A$2:$B$21,2,FALSE)&"'!AI:AI"),MATCH($K6,INDIRECT("'"&VLOOKUP($C6,ModMap!$A$2:$B$21,2,FALSE)&"'!$K:$K"),0)),"")} | AJ6: No | AK6: {=IFERROR(INDEX(INDIRECT("'"&VLOOKUP($C6,ModMap!$A$2:$B$21,2,FALSE)&"'!AK:AK"),MATCH($K6,INDIRECT("'"&VLOOKUP($C6,ModMap!$A$2:$B$21,2,FALSE)&"'!$K:$K"),0)),"")} -> N/A | AL6: {=IFERROR(INDEX(INDIRECT("'"&VLOOKUP($C6,ModMap!$A$2:$B$21,2,FALSE)&"'!AL:AL"),MATCH($K6,INDIRECT("'"&VLOOKUP($C6,ModMap!$A$2:$B$21,2,FALSE)&"'!$K:$K"),0)),"")} | AM6: =IF(AND(U6="Yes",V6<>"Done",V6<>"Deferred",V6<>"N/A"),1,0)+IF(AND(X6="Yes",Y6<>"Done",Y6<>"Deferred",Y6<>"N/A"),1,0)+IF(AND(AA6="Yes",AB6<>"Done",AB6<>"Deferred",AB6<>"N/A"),1,0)+IF(AND(AD6="Yes",AE6<>"Done",AE6<>"Deferred",AE6<>"N/A"),1,0)+IF(AND(AG6="Yes",AH6<>"Done",AH6<>"Deferred",AH6<>"N/A"),1,0)+IF(AND(AJ6="Yes",AK6<>"Done",AK6<>"Deferred",AK6<>"N/A"),1,0) -> 0 | AN6: =IF((IF(U6="Yes",1,0)+IF(X6="Yes",1,0)+IF(AA6="Yes",1,0)+IF(AD6="Yes",1,0)+IF(AG6="Yes",1,0)+IF(AJ6="Yes",1,0))=0,"N/A",IF((IF(AND(U6="Yes",V6="Blocked"),1,0)+IF(AND(X6="Yes",Y6="Blocked"),1,0)+IF(AND(AA6="Yes",AB6="Blocked"),1,0)+IF(AND(AD6="Yes",AE6="Blocked"),1,0)+IF(AND(AG6="Yes",AH6="Blocked"),1,0)+IF(AND(AJ6="Yes",AK6="Blocked"),1,0))>0,"Blocked",IF((IF(AND(U6="Yes",V6="Done"),1,0)+IF(AND(X6="Yes",Y6="Done"),1,0)+IF(AND(AA6="Yes",AB6="Done"),1,0)+IF(AND(AD6="Yes",AE6="Done"),1,0)+IF(AND(AG6="Yes",AH6="Done"),1,0)+IF(AND(AJ6="Yes",AK6="Done"),1,0))=(IF(U6="Yes",1,0)+IF(X6="Yes",1,0)+IF(AA6="Yes",1,0)+IF(AD6="Yes",1,0)+IF(AG6="Yes",1,0)+IF(AJ6="Yes",1,0)),"Done",IF((IF(AND(U6="Yes",OR(V6="In Progress",V6="Done",V6="Deferred")),1,0)+IF(AND(X6="Yes",OR(Y6="In Progress",Y6="Done",Y6="Deferred")),1,0)+IF(AND(AA6="Yes",OR(AB6="In Progress",AB6="Done",AB6="Deferred")),1,0)+IF(AND(AD6="Yes",OR(AE6="In Progress",AE6="Done",AE6="Deferred")),1,0)+IF(AND(AG6="Yes",OR(AH6="In Progress",AH6="Done",AH6="Deferred")),1,0)+IF(AND(AJ6="Yes",OR(AK6="In Progress",AK6="Done",AK6="Deferred")),1,0))>0,"In Progress","Not Started")))) -> N/A | AO6: {=IFERROR(INDEX(INDIRECT("'"&VLOOKUP($C6,ModMap!$A$2:$B$21,2,FALSE)&"'!AO:AO"),MATCH($K6,INDIRECT("'"&VLOOKUP($C6,ModMap!$A$2:$B$21,2,FALSE)&"'!$K:$K"),0)),"")} | AP6: {=IFERROR(HYPERLINK("#'"&VLOOKUP($C6,ModMap!$A$2:$B$21,2,FALSE)&"'!V"&MATCH($K6,INDIRECT("'"&VLOOKUP($C6,ModMap!$A$2:$B$21,2,FALSE)&"'!$K:$K"),0),"Edit on module sheet"),"")} -> Edit on module sheet
A7: 5 | B7: 5 | C7: M00 | D7: PRE — Client gates | E7: Web | F7: PRE | G7: PRE — Client gates (must sign before Phase 6 money spine) | H7: PRE.2 | I7: PRE-02 | J7: Decide reception cash policy — clinic retains vs remits to Homeocentrum | K7: PRE-02.02 | L7: Document GST treatment on consult fee, platform fee, and medicine (on which amount, which GSTIN) | M7: Client Decision | N7: Finance / Reception | O7: §9 | P7: Reception payment collection | Q7: Cash, UPI, card or payment link with printed receipt | R7: Account / Reception | S7: Decision | T7: {=IFERROR(INDEX(INDIRECT("'"&VLOOKUP($C7,ModMap!$A$2:$B$21,2,FALSE)&"'!T:T"),MATCH($K7,INDIRECT("'"&VLOOKUP($C7,ModMap!$A$2:$B$21,2,FALSE)&"'!$K:$K"),0)),"")} -> Unassigned | U7: No | V7: {=IFERROR(INDEX(INDIRECT("'"&VLOOKUP($C7,ModMap!$A$2:$B$21,2,FALSE)&"'!V:V"),MATCH($K7,INDIRECT("'"&VLOOKUP($C7,ModMap!$A$2:$B$21,2,FALSE)&"'!$K:$K"),0)),"")} -> N/A | W7: {=IFERROR(INDEX(INDIRECT("'"&VLOOKUP($C7,ModMap!$A$2:$B$21,2,FALSE)&"'!W:W"),MATCH($K7,INDIRECT("'"&VLOOKUP($C7,ModMap!$A$2:$B$21,2,FALSE)&"'!$K:$K"),0)),"")} | X7: No | Y7: {=IFERROR(INDEX(INDIRECT("'"&VLOOKUP($C7,ModMap!$A$2:$B$21,2,FALSE)&"'!Y:Y"),MATCH($K7,INDIRECT("'"&VLOOKUP($C7,ModMap!$A$2:$B$21,2,FALSE)&"'!$K:$K"),0)),"")} -> N/A | Z7: {=IFERROR(INDEX(INDIRECT("'"&VLOOKUP($C7,ModMap!$A$2:$B$21,2,FALSE)&"'!Z:Z"),MATCH($K7,INDIRECT("'"&VLOOKUP($C7,ModMap!$A$2:$B$21,2,FALSE)&"'!$K:$K"),0)),"")} | AA7: No | AB7: {=IFERROR(INDEX(INDIRECT("'"&VLOOKUP($C7,ModMap!$A$2:$B$21,2,FALSE)&"'!AB:AB"),MATCH($K7,INDIRECT("'"&VLOOKUP($C7,ModMap!$A$2:$B$21,2,FALSE)&"'!$K:$K"),0)),"")} -> N/A | AC7: {=IFERROR(INDEX(INDIRECT("'"&VLOOKUP($C7,ModMap!$A$2:$B$21,2,FALSE)&"'!AC:AC"),MATCH($K7,INDIRECT("'"&VLOOKUP($C7,ModMap!$A$2:$B$21,2,FALSE)&"'!$K:$K"),0)),"")} | AD7: No | AE7: {=IFERROR(INDEX(INDIRECT("'"&VLOOKUP($C7,ModMap!$A$2:$B$21,2,FALSE)&"'!AE:AE"),MATCH($K7,INDIRECT("'"&VLOOKUP($C7,ModMap!$A$2:$B$21,2,FALSE)&"'!$K:$K"),0)),"")} -> N/A | AF7: {=IFERROR(INDEX(INDIRECT("'"&VLOOKUP($C7,ModMap!$A$2:$B$21,2,FALSE)&"'!AF:AF"),MATCH($K7,INDIRECT("'"&VLOOKUP($C7,ModMap!$A$2:$B$21,2,FALSE)&"'!$K:$K"),0)),"")} | AG7: No | AH7: {=IFERROR(INDEX(INDIRECT("'"&VLOOKUP($C7,ModMap!$A$2:$B$21,2,FALSE)&"'!AH:AH"),MATCH($K7,INDIRECT("'"&VLOOKUP($C7,ModMap!$A$2:$B$21,2,FALSE)&"'!$K:$K"),0)),"")} -> N/A | AI7: {=IFERROR(INDEX(INDIRECT("'"&VLOOKUP($C7,ModMap!$A$2:$B$21,2,FALSE)&"'!AI:AI"),MATCH($K7,INDIRECT("'"&VLOOKUP($C7,ModMap!$A$2:$B$21,2,FALSE)&"'!$K:$K"),0)),"")} | AJ7: No | AK7: {=IFERROR(INDEX(INDIRECT("'"&VLOOKUP($C7,ModMap!$A$2:$B$21,2,FALSE)&"'!AK:AK"),MATCH($K7,INDIRECT("'"&VLOOKUP($C7,ModMap!$A$2:$B$21,2,FALSE)&"'!$K:$K"),0)),"")} -> N/A | AL7: {=IFERROR(INDEX(INDIRECT("'"&VLOOKUP($C7,ModMap!$A$2:$B$21,2,FALSE)&"'!AL:AL"),MATCH($K7,INDIRECT("'"&VLOOKUP($C7,ModMap!$A$2:$B$21,2,FALSE)&"'!$K:$K"),0)),"")} | AM7: =IF(AND(U7="Yes",V7<>"Done",V7<>"Deferred",V7<>"N/A"),1,0)+IF(AND(X7="Yes",Y7<>"Done",Y7<>"Deferred",Y7<>"N/A"),1,0)+IF(AND(AA7="Yes",AB7<>"Done",AB7<>"Deferred",AB7<>"N/A"),1,0)+IF(AND(AD7="Yes",AE7<>"Done",AE7<>"Deferred",AE7<>"N/A"),1,0)+IF(AND(AG7="Yes",AH7<>"Done",AH7<>"Deferred",AH7<>"N/A"),1,0)+IF(AND(AJ7="Yes",AK7<>"Done",AK7<>"Deferred",AK7<>"N/A"),1,0) -> 0 | AN7: =IF((IF(U7="Yes",1,0)+IF(X7="Yes",1,0)+IF(AA7="Yes",1,0)+IF(AD7="Yes",1,0)+IF(AG7="Yes",1,0)+IF(AJ7="Yes",1,0))=0,"N/A",IF((IF(AND(U7="Yes",V7="Blocked"),1,0)+IF(AND(X7="Yes",Y7="Blocked"),1,0)+IF(AND(AA7="Yes",AB7="Blocked"),1,0)+IF(AND(AD7="Yes",AE7="Blocked"),1,0)+IF(AND(AG7="Yes",AH7="Blocked"),1,0)+IF(AND(AJ7="Yes",AK7="Blocked"),1,0))>0,"Blocked",IF((IF(AND(U7="Yes",V7="Done"),1,0)+IF(AND(X7="Yes",Y7="Done"),1,0)+IF(AND(AA7="Yes",AB7="Done"),1,0)+IF(AND(AD7="Yes",AE7="Done"),1,0)+IF(AND(AG7="Yes",AH7="Done"),1,0)+IF(AND(AJ7="Yes",AK7="Done"),1,0))=(IF(U7="Yes",1,0)+IF(X7="Yes",1,0)+IF(AA7="Yes",1,0)+IF(AD7="Yes",1,0)+IF(AG7="Yes",1,0)+IF(AJ7="Yes",1,0)),"Done",IF((IF(AND(U7="Yes",OR(V7="In Progress",V7="Done",V7="Deferred")),1,0)+IF(AND(X7="Yes",OR(Y7="In Progress",Y7="Done",Y7="Deferred")),1,0)+IF(AND(AA7="Yes",OR(AB7="In Progress",AB7="Done",AB7="Deferred")),1,0)+IF(AND(AD7="Yes",OR(AE7="In Progress",AE7="Done",AE7="Deferred")),1,0)+IF(AND(AG7="Yes",OR(AH7="In Progress",AH7="Done",AH7="Deferred")),1,0)+IF(AND(AJ7="Yes",OR(AK7="In Progress",AK7="Done",AK7="Deferred")),1,0))>0,"In Progress","Not Started")))) -> N/A | AO7: {=IFERROR(INDEX(INDIRECT("'"&VLOOKUP($C7,ModMap!$A$2:$B$21,2,FALSE)&"'!AO:AO"),MATCH($K7,INDIRECT("'"&VLOOKUP($C7,ModMap!$A$2:$B$21,2,FALSE)&"'!$K:$K"),0)),"")} | AP7: {=IFERROR(HYPERLINK("#'"&VLOOKUP($C7,ModMap!$A$2:$B$21,2,FALSE)&"'!V"&MATCH($K7,INDIRECT("'"&VLOOKUP($C7,ModMap!$A$2:$B$21,2,FALSE)&"'!$K:$K"),0),"Edit on module sheet"),"")} -> Edit on module sheet
A8: 6 | B8: 6 | C8: M00 | D8: PRE — Client gates | E8: Web | F8: PRE | G8: PRE — Client gates (must sign before Phase 6 money spine) | H8: PRE.2 | I8: PRE-02 | J8: Decide reception cash policy — clinic retains vs remits to Homeocentrum | K8: PRE-02.03 | L8: Confirm commission %, settlement hold T+N days, invoice numbering series — configuration not code | M8: Configuration | N8: Finance / Reception | O8: §9 | P8: Reception payment collection | Q8: Cash, UPI, card or payment link with printed receipt | R8: Account / Reception | S8: Configuration | T8: {=IFERROR(INDEX(INDIRECT("'"&VLOOKUP($C8,ModMap!$A$2:$B$21,2,FALSE)&"'!T:T"),MATCH($K8,INDIRECT("'"&VLOOKUP($C8,ModMap!$A$2:$B$21,2,FALSE)&"'!$K:$K"),0)),"")} -> Unassigned | U8: No | V8: {=IFERROR(INDEX(INDIRECT("'"&VLOOKUP($C8,ModMap!$A$2:$B$21,2,FALSE)&"'!V:V"),MATCH($K8,INDIRECT("'"&VLOOKUP($C8,ModMap!$A$2:$B$21,2,FALSE)&"'!$K:$K"),0)),"")} -> N/A | W8: {=IFERROR(INDEX(INDIRECT("'"&VLOOKUP($C8,ModMap!$A$2:$B$21,2,FALSE)&"'!W:W"),MATCH($K8,INDIRECT("'"&VLOOKUP($C8,ModMap!$A$2:$B$21,2,FALSE)&"'!$K:$K"),0)),"")} | X8: Yes | Y8: {=IFERROR(INDEX(INDIRECT("'"&VLOOKUP($C8,ModMap!$A$2:$B$21,2,FALSE)&"'!Y:Y"),MATCH($K8,INDIRECT("'"&VLOOKUP($C8,ModMap!$A$2:$B$21,2,FALSE)&"'!$K:$K"),0)),"")} -> Not Started | Z8: {=IFERROR(INDEX(INDIRECT("'"&VLOOKUP($C8,ModMap!$A$2:$B$21,2,FALSE)&"'!Z:Z"),MATCH($K8,INDIRECT("'"&VLOOKUP($C8,ModMap!$A$2:$B$21,2,FALSE)&"'!$K:$K"),0)),"")} -> Unassigned | AA8: No | AB8: {=IFERROR(INDEX(INDIRECT("'"&VLOOKUP($C8,ModMap!$A$2:$B$21,2,FALSE)&"'!AB:AB"),MATCH($K8,INDIRECT("'"&VLOOKUP($C8,ModMap!$A$2:$B$21,2,FALSE)&"'!$K:$K"),0)),"")} -> N/A | AC8: {=IFERROR(INDEX(INDIRECT("'"&VLOOKUP($C8,ModMap!$A$2:$B$21,2,FALSE)&"'!AC:AC"),MATCH($K8,INDIRECT("'"&VLOOKUP($C8,ModMap!$A$2:$B$21,2,FALSE)&"'!$K:$K"),0)),"")} | AD8: No | AE8: {=IFERROR(INDEX(INDIRECT("'"&VLOOKUP($C8,ModMap!$A$2:$B$21,2,FALSE)&"'!AE:AE"),MATCH($K8,INDIRECT("'"&VLOOKUP($C8,ModMap!$A$2:$B$21,2,FALSE)&"'!$K:$K"),0)),"")} -> N/A | AF8: {=IFERROR(INDEX(INDIRECT("'"&VLOOKUP($C8,ModMap!$A$2:$B$21,2,FALSE)&"'!AF:AF"),MATCH($K8,INDIRECT("'"&VLOOKUP($C8,ModMap!$A$2:$B$21,2,FALSE)&"'!$K:$K"),0)),"")} | AG8: No | AH8: {=IFERROR(INDEX(INDIRECT("'"&VLOOKUP($C8,ModMap!$A$2:$B$21,2,FALSE)&"'!AH:AH"),MATCH($K8,INDIRECT("'"&VLOOKUP($C8,ModMap!$A$2:$B$21,2,FALSE)&"'!$K:$K"),0)),"")} -> N/A | AI8: {=IFERROR(INDEX(INDIRECT("'"&VLOOKUP($C8,ModMap!$A$2:$B$21,2,FALSE)&"'!AI:AI"),MATCH($K8,INDIRECT("'"&VLOOKUP($C8,ModMap!$A$2:$B$21,2,FALSE)&"'!$K:$K"),0)),"")} | AJ8: No | AK8: {=IFERROR(INDEX(INDIRECT("'"&VLOOKUP($C8,ModMap!$A$2:$B$21,2,FALSE)&"'!AK:AK"),MATCH($K8,INDIRECT("'"&VLOOKUP($C8,ModMap!$A$2:$B$21,2,FALSE)&"'!$K:$K"),0)),"")} -> N/A | AL8: {=IFERROR(INDEX(INDIRECT("'"&VLOOKUP($C8,ModMap!$A$2:$B$21,2,FALSE)&"'!AL:AL"),MATCH($K8,INDIRECT("'"&VLOOKUP($C8,ModMap!$A$2:$B$21,2,FALSE)&"'!$K:$K"),0)),"")} | AM8: =IF(AND(U8="Yes",V8<>"Done",V8<>"Deferred",V8<>"N/A"),1,0)+IF(AND(X8="Yes",Y8<>"Done",Y8<>"Deferred",Y8<>"N/A"),1,0)+IF(AND(AA8="Yes",AB8<>"Done",AB8<>"Deferred",AB8<>"N/A"),1,0)+IF(AND(AD8="Yes",AE8<>"Done",AE8<>"Deferred",AE8<>"N/A"),1,0)+IF(AND(AG8="Yes",AH8<>"Done",AH8<>"Deferred",AH8<>"N/A"),1,0)+IF(AND(AJ8="Yes",AK8<>"Done",AK8<>"Deferred",AK8<>"N/A"),1,0) -> 1 | AN8: =IF((IF(U8="Yes",1,0)+IF(X8="Yes",1,0)+IF(AA8="Yes",1,0)+IF(AD8="Yes",1,0)+IF(AG8="Yes",1,0)+IF(AJ8="Yes",1,0))=0,"N/A",IF((IF(AND(U8="Yes",V8="Blocked"),1,0)+IF(AND(X8="Yes",Y8="Blocked"),1,0)+IF(AND(AA8="Yes",AB8="Blocked"),1,0)+IF(AND(AD8="Yes",AE8="Blocked"),1,0)+IF(AND(AG8="Yes",AH8="Blocked"),1,0)+IF(AND(AJ8="Yes",AK8="Blocked"),1,0))>0,"Blocked",IF((IF(AND(U8="Yes",V8="Done"),1,0)+IF(AND(X8="Yes",Y8="Done"),1,0)+IF(AND(AA8="Yes",AB8="Done"),1,0)+IF(AND(AD8="Yes",AE8="Done"),1,0)+IF(AND(AG8="Yes",AH8="Done"),1,0)+IF(AND(AJ8="Yes",AK8="Done"),1,0))=(IF(U8="Yes",1,0)+IF(X8="Yes",1,0)+IF(AA8="Yes",1,0)+IF(AD8="Yes",1,0)+IF(AG8="Yes",1,0)+IF(AJ8="Yes",1,0)),"Done",IF((IF(AND(U8="Yes",OR(V8="In Progress",V8="Done",V8="Deferred")),1,0)+IF(AND(X8="Yes",OR(Y8="In Progress",Y8="Done",Y8="Deferred")),1,0)+IF(AND(AA8="Yes",OR(AB8="In Progress",AB8="Done",AB8="Deferred")),1,0)+IF(AND(AD8="Yes",OR(AE8="In Progress",AE8="Done",AE8="Deferred")),1,0)+IF(AND(AG8="Yes",OR(AH8="In Progress",AH8="Done",AH8="Deferred")),1,0)+IF(AND(AJ8="Yes",OR(AK8="In Progress",AK8="Done",AK8="Deferred")),1,0))>0,"In Progress","Not Started")))) -> Not Started | AO8: {=IFERROR(INDEX(INDIRECT("'"&VLOOKUP($C8,ModMap!$A$2:$B$21,2,FALSE)&"'!AO:AO"),MATCH($K8,INDIRECT("'"&VLOOKUP($C8,ModMap!$A$2:$B$21,2,FALSE)&"'!$K:$K"),0)),"")} | AP8: {=IFERROR(HYPERLINK("#'"&VLOOKUP($C8,ModMap!$A$2:$B$21,2,FALSE)&"'!V"&MATCH($K8,INDIRECT("'"&VLOOKUP($C8,ModMap!$A$2:$B$21,2,FALSE)&"'!$K:$K"),0),"Edit on module sheet"),"")} -> Edit on module sheet
A9: 7 | B9: 7 | C9: M00 | D9: PRE — Client gates | E9: Web | F9: PRE | G9: PRE — Client gates (must sign before Phase 6 money spine) | H9: PRE.3 | I9: PRE-03 | J9: Vendor and legal gates — video SDK, SMS, WhatsApp, push, DPDP copy | K9: PRE-03.01 | L9: Select in-browser + mobile video vendor (Agora / Twilio / Daily / WebRTC self-host) — required for §10 | M9: Client Decision | N9: Platform | O9: §10 + §14 + §17 | P9: Telemedicine + notifications + consent | Q9: Video consultation; SMS/WhatsApp/Push/Email; consent records | R9: Shared | S9: Decision | T9: {=IFERROR(INDEX(INDIRECT("'"&VLOOKUP($C9,ModMap!$A$2:$B$21,2,FALSE)&"'!T:T"),MATCH($K9,INDIRECT("'"&VLOOKUP($C9,ModMap!$A$2:$B$21,2,FALSE)&"'!$K:$K"),0)),"")} -> Unassigned | U9: No | V9: {=IFERROR(INDEX(INDIRECT("'"&VLOOKUP($C9,ModMap!$A$2:$B$21,2,FALSE)&"'!V:V"),MATCH($K9,INDIRECT("'"&VLOOKUP($C9,ModMap!$A$2:$B$21,2,FALSE)&"'!$K:$K"),0)),"")} -> N/A | W9: {=IFERROR(INDEX(INDIRECT("'"&VLOOKUP($C9,ModMap!$A$2:$B$21,2,FALSE)&"'!W:W"),MATCH($K9,INDIRECT("'"&VLOOKUP($C9,ModMap!$A$2:$B$21,2,FALSE)&"'!$K:$K"),0)),"")} | X9: No | Y9: {=IFERROR(INDEX(INDIRECT("'"&VLOOKUP($C9,ModMap!$A$2:$B$21,2,FALSE)&"'!Y:Y"),MATCH($K9,INDIRECT("'"&VLOOKUP($C9,ModMap!$A$2:$B$21,2,FALSE)&"'!$K:$K"),0)),"")} -> N/A | Z9: {=IFERROR(INDEX(INDIRECT("'"&VLOOKUP($C9,ModMap!$A$2:$B$21,2,FALSE)&"'!Z:Z"),MATCH($K9,INDIRECT("'"&VLOOKUP($C9,ModMap!$A$2:$B$21,2,FALSE)&"'!$K:$K"),0)),"")} | AA9: No | AB9: {=IFERROR(INDEX(INDIRECT("'"&VLOOKUP($C9,ModMap!$A$2:$B$21,2,FALSE)&"'!AB:AB"),MATCH($K9,INDIRECT("'"&VLOOKUP($C9,ModMap!$A$2:$B$21,2,FALSE)&"'!$K:$K"),0)),"")} -> N/A | AC9: {=IFERROR(INDEX(INDIRECT("'"&VLOOKUP($C9,ModMap!$A$2:$B$21,2,FALSE)&"'!AC:AC"),MATCH($K9,INDIRECT("'"&VLOOKUP($C9,ModMap!$A$2:$B$21,2,FALSE)&"'!$K:$K"),0)),"")} | AD9: No | AE9: {=IFERROR(INDEX(INDIRECT("'"&VLOOKUP($C9,ModMap!$A$2:$B$21,2,FALSE)&"'!AE:AE"),MATCH($K9,INDIRECT("'"&VLOOKUP($C9,ModMap!$A$2:$B$21,2,FALSE)&"'!$K:$K"),0)),"")} -> N/A | AF9: {=IFERROR(INDEX(INDIRECT("'"&VLOOKUP($C9,ModMap!$A$2:$B$21,2,FALSE)&"'!AF:AF"),MATCH($K9,INDIRECT("'"&VLOOKUP($C9,ModMap!$A$2:$B$21,2,FALSE)&"'!$K:$K"),0)),"")} | AG9: No | AH9: {=IFERROR(INDEX(INDIRECT("'"&VLOOKUP($C9,ModMap!$A$2:$B$21,2,FALSE)&"'!AH:AH"),MATCH($K9,INDIRECT("'"&VLOOKUP($C9,ModMap!$A$2:$B$21,2,FALSE)&"'!$K:$K"),0)),"")} -> N/A | AI9: {=IFERROR(INDEX(INDIRECT("'"&VLOOKUP($C9,ModMap!$A$2:$B$21,2,FALSE)&"'!AI:AI"),MATCH($K9,INDIRECT("'"&VLOOKUP($C9,ModMap!$A$2:$B$21,2,FALSE)&"'!$K:$K"),0)),"")} | AJ9: Yes | AK9: {=IFERROR(INDEX(INDIRECT("'"&VLOOKUP($C9,ModMap!$A$2:$B$21,2,FALSE)&"'!AK:AK"),MATCH($K9,INDIRECT("'"&VLOOKUP($C9,ModMap!$A$2:$B$21,2,FALSE)&"'!$K:$K"),0)),"")} -> Not Started | AL9: {=IFERROR(INDEX(INDIRECT("'"&VLOOKUP($C9,ModMap!$A$2:$B$21,2,FALSE)&"'!AL:AL"),MATCH($K9,INDIRECT("'"&VLOOKUP($C9,ModMap!$A$2:$B$21,2,FALSE)&"'!$K:$K"),0)),"")} -> Unassigned | AM9: =IF(AND(U9="Yes",V9<>"Done",V9<>"Deferred",V9<>"N/A"),1,0)+IF(AND(X9="Yes",Y9<>"Done",Y9<>"Deferred",Y9<>"N/A"),1,0)+IF(AND(AA9="Yes",AB9<>"Done",AB9<>"Deferred",AB9<>"N/A"),1,0)+IF(AND(AD9="Yes",AE9<>"Done",AE9<>"Deferred",AE9<>"N/A"),1,0)+IF(AND(AG9="Yes",AH9<>"Done",AH9<>"Deferred",AH9<>"N/A"),1,0)+IF(AND(AJ9="Yes",AK9<>"Done",AK9<>"Deferred",AK9<>"N/A"),1,0) -> 1 | AN9: =IF((IF(U9="Yes",1,0)+IF(X9="Yes",1,0)+IF(AA9="Yes",1,0)+IF(AD9="Yes",1,0)+IF(AG9="Yes",1,0)+IF(AJ9="Yes",1,0))=0,"N/A",IF((IF(AND(U9="Yes",V9="Blocked"),1,0)+IF(AND(X9="Yes",Y9="Blocked"),1,0)+IF(AND(AA9="Yes",AB9="Blocked"),1,0)+IF(AND(AD9="Yes",AE9="Blocked"),1,0)+IF(AND(AG9="Yes",AH9="Blocked"),1,0)+IF(AND(AJ9="Yes",AK9="Blocked"),1,0))>0,"Blocked",IF((IF(AND(U9="Yes",V9="Done"),1,0)+IF(AND(X9="Yes",Y9="Done"),1,0)+IF(AND(AA9="Yes",AB9="Done"),1,0)+IF(AND(AD9="Yes",AE9="Done"),1,0)+IF(AND(AG9="Yes",AH9="Done"),1,0)+IF(AND(AJ9="Yes",AK9="Done"),1,0))=(IF(U9="Yes",1,0)+IF(X9="Yes",1,0)+IF(AA9="Yes",1,0)+IF(AD9="Yes",1,0)+IF(AG9="Yes",1,0)+IF(AJ9="Yes",1,0)),"Done",IF((IF(AND(U9="Yes",OR(V9="In Progress",V9="Done",V9="Deferred")),1,0)+IF(AND(X9="Yes",OR(Y9="In Progress",Y9="Done",Y9="Deferred")),1,0)+IF(AND(AA9="Yes",OR(AB9="In Progress",AB9="Done",AB9="Deferred")),1,0)+IF(AND(AD9="Yes",OR(AE9="In Progress",AE9="Done",AE9="Deferred")),1,0)+IF(AND(AG9="Yes",OR(AH9="In Progress",AH9="Done",AH9="Deferred")),1,0)+IF(AND(AJ9="Yes",OR(AK9="In Progress",AK9="Done",AK9="Deferred")),1,0))>0,"In Progress","Not Started")))) -> Not Started | AO9: {=IFERROR(INDEX(INDIRECT("'"&VLOOKUP($C9,ModMap!$A$2:$B$21,2,FALSE)&"'!AO:AO"),MATCH($K9,INDIRECT("'"&VLOOKUP($C9,ModMap!$A$2:$B$21,2,FALSE)&"'!$K:$K"),0)),"")} | AP9: {=IFERROR(HYPERLINK("#'"&VLOOKUP($C9,ModMap!$A$2:$B$21,2,FALSE)&"'!V"&MATCH($K9,INDIRECT("'"&VLOOKUP($C9,ModMap!$A$2:$B$21,2,FALSE)&"'!$K:$K"),0),"Edit on module sheet"),"")} -> Edit on module sheet
A10: 8 | B10: 8 | C10: M00 | D10: PRE — Client gates | E10: Web | F10: PRE | G10: PRE — Client gates (must sign before Phase 6 money spine) | H10: PRE.3 | I10: PRE-03 | J10: Vendor and legal gates — video SDK, SMS, WhatsApp, push, DPDP copy | K10: PRE-03.02 | L10: Select SMS provider (MSG91 / Twilio / etc.) and confirm DLT templates for appointment/OTP/cancel | M10: Client Decision | N10: Platform | O10: §10 + §14 + §17 | P10: Telemedicine + notifications + consent | Q10: Video consultation; SMS/WhatsApp/Push/Email; consent records | R10: Shared | S10: Decision | T10: {=IFERROR(INDEX(INDIRECT("'"&VLOOKUP($C10,ModMap!$A$2:$B$21,2,FALSE)&"'!T:T"),MATCH($K10,INDIRECT("'"&VLOOKUP($C10,ModMap!$A$2:$B$21,2,FALSE)&"'!$K:$K"),0)),"")} -> Unassigned | U10: No | V10: {=IFERROR(INDEX(INDIRECT("'"&VLOOKUP($C10,ModMap!$A$2:$B$21,2,FALSE)&"'!V:V"),MATCH($K10,INDIRECT("'"&VLOOKUP($C10,ModMap!$A$2:$B$21,2,FALSE)&"'!$K:$K"),0)),"")} -> N/A | W10: {=IFERROR(INDEX(INDIRECT("'"&VLOOKUP($C10,ModMap!$A$2:$B$21,2,FALSE)&"'!W:W"),MATCH($K10,INDIRECT("'"&VLOOKUP($C10,ModMap!$A$2:$B$21,2,FALSE)&"'!$K:$K"),0)),"")} | X10: No | Y10: {=IFERROR(INDEX(INDIRECT("'"&VLOOKUP($C10,ModMap!$A$2:$B$21,2,FALSE)&"'!Y:Y"),MATCH($K10,INDIRECT("'"&VLOOKUP($C10,ModMap!$A$2:$B$21,2,FALSE)&"'!$K:$K"),0)),"")} -> N/A | Z10: {=IFERROR(INDEX(INDIRECT("'"&VLOOKUP($C10,ModMap!$A$2:$B$21,2,FALSE)&"'!Z:Z"),MATCH($K10,INDIRECT("'"&VLOOKUP($C10,ModMap!$A$2:$B$21,2,FALSE)&"'!$K:$K"),0)),"")} | AA10: No | AB10: {=IFERROR(INDEX(INDIRECT("'"&VLOOKUP($C10,ModMap!$A$2:$B$21,2,FALSE)&"'!AB:AB"),MATCH($K10,INDIRECT("'"&VLOOKUP($C10,ModMap!$A$2:$B$21,2,FALSE)&"'!$K:$K"),0)),"")} -> N/A | AC10: {=IFERROR(INDEX(INDIRECT("'"&VLOOKUP($C10,ModMap!$A$2:$B$21,2,FALSE)&"'!AC:AC"),MATCH($K10,INDIRECT("'"&VLOOKUP($C10,ModMap!$A$2:$B$21,2,FALSE)&"'!$K:$K"),0)),"")} | AD10: No | AE10: {=IFERROR(INDEX(INDIRECT("'"&VLOOKUP($C10,ModMap!$A$2:$B$21,2,FALSE)&"'!AE:AE"),MATCH($K10,INDIRECT("'"&VLOOKUP($C10,ModMap!$A$2:$B$21,2,FALSE)&"'!$K:$K"),0)),"")} -> N/A | AF10: {=IFERROR(INDEX(INDIRECT("'"&VLOOKUP($C10,ModMap!$A$2:$B$21,2,FALSE)&"'!AF:AF"),MATCH($K10,INDIRECT("'"&VLOOKUP($C10,ModMap!$A$2:$B$21,2,FALSE)&"'!$K:$K"),0)),"")} | AG10: No | AH10: {=IFERROR(INDEX(INDIRECT("'"&VLOOKUP($C10,ModMap!$A$2:$B$21,2,FALSE)&"'!AH:AH"),MATCH($K10,INDIRECT("'"&VLOOKUP($C10,ModMap!$A$2:$B$21,2,FALSE)&"'!$K:$K"),0)),"")} -> N/A | AI10: {=IFERROR(INDEX(INDIRECT("'"&VLOOKUP($C10,ModMap!$A$2:$B$21,2,FALSE)&"'!AI:AI"),MATCH($K10,INDIRECT("'"&VLOOKUP($C10,ModMap!$A$2:$B$21,2,FALSE)&"'!$K:$K"),0)),"")} | AJ10: Yes | AK10: {=IFERROR(INDEX(INDIRECT("'"&VLOOKUP($C10,ModMap!$A$2:$B$21,2,FALSE)&"'!AK:AK"),MATCH($K10,INDIRECT("'"&VLOOKUP($C10,ModMap!$A$2:$B$21,2,FALSE)&"'!$K:$K"),0)),"")} -> Not Started | AL10: {=IFERROR(INDEX(INDIRECT("'"&VLOOKUP($C10,ModMap!$A$2:$B$21,2,FALSE)&"'!AL:AL"),MATCH($K10,INDIRECT("'"&VLOOKUP($C10,ModMap!$A$2:$B$21,2,FALSE)&"'!$K:$K"),0)),"")} -> Unassigned | AM10: =IF(AND(U10="Yes",V10<>"Done",V10<>"Deferred",V10<>"N/A"),1,0)+IF(AND(X10="Yes",Y10<>"Done",Y10<>"Deferred",Y10<>"N/A"),1,0)+IF(AND(AA10="Yes",AB10<>"Done",AB10<>"Deferred",AB10<>"N/A"),1,0)+IF(AND(AD10="Yes",AE10<>"Done",AE10<>"Deferred",AE10<>"N/A"),1,0)+IF(AND(AG10="Yes",AH10<>"Done",AH10<>"Deferred",AH10<>"N/A"),1,0)+IF(AND(AJ10="Yes",AK10<>"Done",AK10<>"Deferred",AK10<>"N/A"),1,0) -> 1 | AN10: =IF((IF(U10="Yes",1,0)+IF(X10="Yes",1,0)+IF(AA10="Yes",1,0)+IF(AD10="Yes",1,0)+IF(AG10="Yes",1,0)+IF(AJ10="Yes",1,0))=0,"N/A",IF((IF(AND(U10="Yes",V10="Blocked"),1,0)+IF(AND(X10="Yes",Y10="Blocked"),1,0)+IF(AND(AA10="Yes",AB10="Blocked"),1,0)+IF(AND(AD10="Yes",AE10="Blocked"),1,0)+IF(AND(AG10="Yes",AH10="Blocked"),1,0)+IF(AND(AJ10="Yes",AK10="Blocked"),1,0))>0,"Blocked",IF((IF(AND(U10="Yes",V10="Done"),1,0)+IF(AND(X10="Yes",Y10="Done"),1,0)+IF(AND(AA10="Yes",AB10="Done"),1,0)+IF(AND(AD10="Yes",AE10="Done"),1,0)+IF(AND(AG10="Yes",AH10="Done"),1,0)+IF(AND(AJ10="Yes",AK10="Done"),1,0))=(IF(U10="Yes",1,0)+IF(X10="Yes",1,0)+IF(AA10="Yes",1,0)+IF(AD10="Yes",1,0)+IF(AG10="Yes",1,0)+IF(AJ10="Yes",1,0)),"Done",IF((IF(AND(U10="Yes",OR(V10="In Progress",V10="Done",V10="Deferred")),1,0)+IF(AND(X10="Yes",OR(Y10="In Progress",Y10="Done",Y10="Deferred")),1,0)+IF(AND(AA10="Yes",OR(AB10="In Progress",AB10="Done",AB10="Deferred")),1,0)+IF(AND(AD10="Yes",OR(AE10="In Progress",AE10="Done",AE10="Deferred")),1,0)+IF(AND(AG10="Yes",OR(AH10="In Progress",AH10="Done",AH10="Deferred")),1,0)+IF(AND(AJ10="Yes",OR(AK10="In Progress",AK10="Done",AK10="Deferred")),1,0))>0,"In Progress","Not Started")))) -> Not Started | AO10: {=IFERROR(INDEX(INDIRECT("'"&VLOOKUP($C10,ModMap!$A$2:$B$21,2,FALSE)&"'!AO:AO"),MATCH($K10,INDIRECT("'"&VLOOKUP($C10,ModMap!$A$2:$B$21,2,FALSE)&"'!$K:$K"),0)),"")} | AP10: {=IFERROR(HYPERLINK("#'"&VLOOKUP($C10,ModMap!$A$2:$B$21,2,FALSE)&"'!V"&MATCH($K10,INDIRECT("'"&VLOOKUP($C10,ModMap!$A$2:$B$21,2,FALSE)&"'!$K:$K"),0),"Edit on module sheet"),"")} -> Edit on module sheet
A11: 9 | B11: 9 | C11: M00 | D11: PRE — Client gates | E11: Web | F11: PRE | G11: PRE — Client gates (must sign before Phase 6 money spine) | H11: PRE.3 | I11: PRE-03 | J11: Vendor and legal gates — video SDK, SMS, WhatsApp, push, DPDP copy | K11: PRE-03.03 | L11: Legal: privacy (data protection, recording, pharmacy consent) and terms (payments, refunds, telemedicine, medicine orders) drafted for §4 + §17 | M11: Client Decision | N11: Platform | O11: §10 + §14 + §17 | P11: Telemedicine + notifications + consent | Q11: Video consultation; SMS/WhatsApp/Push/Email; consent records | R11: Shared | S11: Legal | T11: {=IFERROR(INDEX(INDIRECT("'"&VLOOKUP($C11,ModMap!$A$2:$B$21,2,FALSE)&"'!T:T"),MATCH($K11,INDIRECT("'"&VLOOKUP($C11,ModMap!$A$2:$B$21,2,FALSE)&"'!$K:$K"),0)),"")} -> Unassigned | U11: No | V11: {=IFERROR(INDEX(INDIRECT("'"&VLOOKUP($C11,ModMap!$A$2:$B$21,2,FALSE)&"'!V:V"),MATCH($K11,INDIRECT("'"&VLOOKUP($C11,ModMap!$A$2:$B$21,2,FALSE)&"'!$K:$K"),0)),"")} -> N/A | W11: {=IFERROR(INDEX(INDIRECT("'"&VLOOKUP($C11,ModMap!$A$2:$B$21,2,FALSE)&"'!W:W"),MATCH($K11,INDIRECT("'"&VLOOKUP($C11,ModMap!$A$2:$B$21,2,FALSE)&"'!$K:$K"),0)),"")} | X11: No | Y11: {=IFERROR(INDEX(INDIRECT("'"&VLOOKUP($C11,ModMap!$A$2:$B$21,2,FALSE)&"'!Y:Y"),MATCH($K11,INDIRECT("'"&VLOOKUP($C11,ModMap!$A$2:$B$21,2,FALSE)&"'!$K:$K"),0)),"")} -> N/A | Z11: {=IFERROR(INDEX(INDIRECT("'"&VLOOKUP($C11,ModMap!$A$2:$B$21,2,FALSE)&"'!Z:Z"),MATCH($K11,INDIRECT("'"&VLOOKUP($C11,ModMap!$A$2:$B$21,2,FALSE)&"'!$K:$K"),0)),"")} | AA11: No | AB11: {=IFERROR(INDEX(INDIRECT("'"&VLOOKUP($C11,ModMap!$A$2:$B$21,2,FALSE)&"'!AB:AB"),MATCH($K11,INDIRECT("'"&VLOOKUP($C11,ModMap!$A$2:$B$21,2,FALSE)&"'!$K:$K"),0)),"")} -> N/A | AC11: {=IFERROR(INDEX(INDIRECT("'"&VLOOKUP($C11,ModMap!$A$2:$B$21,2,FALSE)&"'!AC:AC"),MATCH($K11,INDIRECT("'"&VLOOKUP($C11,ModMap!$A$2:$B$21,2,FALSE)&"'!$K:$K"),0)),"")} | AD11: No | AE11: {=IFERROR(INDEX(INDIRECT("'"&VLOOKUP($C11,ModMap!$A$2:$B$21,2,FALSE)&"'!AE:AE"),MATCH($K11,INDIRECT("'"&VLOOKUP($C11,ModMap!$A$2:$B$21,2,FALSE)&"'!$K:$K"),0)),"")} -> N/A | AF11: {=IFERROR(INDEX(INDIRECT("'"&VLOOKUP($C11,ModMap!$A$2:$B$21,2,FALSE)&"'!AF:AF"),MATCH($K11,INDIRECT("'"&VLOOKUP($C11,ModMap!$A$2:$B$21,2,FALSE)&"'!$K:$K"),0)),"")} | AG11: No | AH11: {=IFERROR(INDEX(INDIRECT("'"&VLOOKUP($C11,ModMap!$A$2:$B$21,2,FALSE)&"'!AH:AH"),MATCH($K11,INDIRECT("'"&VLOOKUP($C11,ModMap!$A$2:$B$21,2,FALSE)&"'!$K:$K"),0)),"")} -> N/A | AI11: {=IFERROR(INDEX(INDIRECT("'"&VLOOKUP($C11,ModMap!$A$2:$B$21,2,FALSE)&"'!AI:AI"),MATCH($K11,INDIRECT("'"&VLOOKUP($C11,ModMap!$A$2:$B$21,2,FALSE)&"'!$K:$K"),0)),"")} | AJ11: No | AK11: {=IFERROR(INDEX(INDIRECT("'"&VLOOKUP($C11,ModMap!$A$2:$B$21,2,FALSE)&"'!AK:AK"),MATCH($K11,INDIRECT("'"&VLOOKUP($C11,ModMap!$A$2:$B$21,2,FALSE)&"'!$K:$K"),0)),"")} -> N/A | AL11: {=IFERROR(INDEX(INDIRECT("'"&VLOOKUP($C11,ModMap!$A$2:$B$21,2,FALSE)&"'!AL:AL"),MATCH($K11,INDIRECT("'"&VLOOKUP($C11,ModMap!$A$2:$B$21,2,FALSE)&"'!$K:$K"),0)),"")} | AM11: =IF(AND(U11="Yes",V11<>"Done",V11<>"Deferred",V11<>"N/A"),1,0)+IF(AND(X11="Yes",Y11<>"Done",Y11<>"Deferred",Y11<>"N/A"),1,0)+IF(AND(AA11="Yes",AB11<>"Done",AB11<>"Deferred",AB11<>"N/A"),1,0)+IF(AND(AD11="Yes",AE11<>"Done",AE11<>"Deferred",AE11<>"N/A"),1,0)+IF(AND(AG11="Yes",AH11<>"Done",AH11<>"Deferred",AH11<>"N/A"),1,0)+IF(AND(AJ11="Yes",AK11<>"Done",AK11<>"Deferred",AK11<>"N/A"),1,0) -> 0 | AN11: =IF((IF(U11="Yes",1,0)+IF(X11="Yes",1,0)+IF(AA11="Yes",1,0)+IF(AD11="Yes",1,0)+IF(AG11="Yes",1,0)+IF(AJ11="Yes",1,0))=0,"N/A",IF((IF(AND(U11="Yes",V11="Blocked"),1,0)+IF(AND(X11="Yes",Y11="Blocked"),1,0)+IF(AND(AA11="Yes",AB11="Blocked"),1,0)+IF(AND(AD11="Yes",AE11="Blocked"),1,0)+IF(AND(AG11="Yes",AH11="Blocked"),1,0)+IF(AND(AJ11="Yes",AK11="Blocked"),1,0))>0,"Blocked",IF((IF(AND(U11="Yes",V11="Done"),1,0)+IF(AND(X11="Yes",Y11="Done"),1,0)+IF(AND(AA11="Yes",AB11="Done"),1,0)+IF(AND(AD11="Yes",AE11="Done"),1,0)+IF(AND(AG11="Yes",AH11="Done"),1,0)+IF(AND(AJ11="Yes",AK11="Done"),1,0))=(IF(U11="Yes",1,0)+IF(X11="Yes",1,0)+IF(AA11="Yes",1,0)+IF(AD11="Yes",1,0)+IF(AG11="Yes",1,0)+IF(AJ11="Yes",1,0)),"Done",IF((IF(AND(U11="Yes",OR(V11="In Progress",V11="Done",V11="Deferred")),1,0)+IF(AND(X11="Yes",OR(Y11="In Progress",Y11="Done",Y11="Deferred")),1,0)+IF(AND(AA11="Yes",OR(AB11="In Progress",AB11="Done",AB11="Deferred")),1,0)+IF(AND(AD11="Yes",OR(AE11="In Progress",AE11="Done",AE11="Deferred")),1,0)+IF(AND(AG11="Yes",OR(AH11="In Progress",AH11="Done",AH11="Deferred")),1,0)+IF(AND(AJ11="Yes",OR(AK11="In Progress",AK11="Done",AK11="Deferred")),1,0))>0,"In Progress","Not Started")))) -> N/A | AO11: {=IFERROR(INDEX(INDIRECT("'"&VLOOKUP($C11,ModMap!$A$2:$B$21,2,FALSE)&"'!AO:AO"),MATCH($K11,INDIRECT("'"&VLOOKUP($C11,ModMap!$A$2:$B$21,2,FALSE)&"'!$K:$K"),0)),"")} | AP11: {=IFERROR(HYPERLINK("#'"&VLOOKUP($C11,ModMap!$A$2:$B$21,2,FALSE)&"'!V"&MATCH($K11,INDIRECT("'"&VLOOKUP($C11,ModMap!$A$2:$B$21,2,FALSE)&"'!$K:$K"),0),"Edit on module sheet"),"")} -> Edit on module sheet
A12: 10 | B12: 10 | C12: M00 | D12: PRE — Client gates | E12: Web | F12: PRE | G12: PRE — Client gates (must sign before Phase 6 money spine) | H12: PRE.3 | I12: PRE-03 | J12: Vendor and legal gates — video SDK, SMS, WhatsApp, push, DPDP copy | K12: PRE-03.04 | L12: OQ: unpaid-booking slot hold duration vs release immediately if patient does not pay | M12: Client Decision | N12: Platform | O12: §10 + §14 + §17 | P12: Telemedicine + notifications + consent | Q12: Video consultation; SMS/WhatsApp/Push/Email; consent records | R12: Shared | S12: Decision | T12: {=IFERROR(INDEX(INDIRECT("'"&VLOOKUP($C12,ModMap!$A$2:$B$21,2,FALSE)&"'!T:T"),MATCH($K12,INDIRECT("'"&VLOOKUP($C12,ModMap!$A$2:$B$21,2,FALSE)&"'!$K:$K"),0)),"")} -> Unassigned | U12: No | V12: {=IFERROR(INDEX(INDIRECT("'"&VLOOKUP($C12,ModMap!$A$2:$B$21,2,FALSE)&"'!V:V"),MATCH($K12,INDIRECT("'"&VLOOKUP($C12,ModMap!$A$2:$B$21,2,FALSE)&"'!$K:$K"),0)),"")} -> N/A | W12: {=IFERROR(INDEX(INDIRECT("'"&VLOOKUP($C12,ModMap!$A$2:$B$21,2,FALSE)&"'!W:W"),MATCH($K12,INDIRECT("'"&VLOOKUP($C12,ModMap!$A$2:$B$21,2,FALSE)&"'!$K:$K"),0)),"")} | X12: No | Y12: {=IFERROR(INDEX(INDIRECT("'"&VLOOKUP($C12,ModMap!$A$2:$B$21,2,FALSE)&"'!Y:Y"),MATCH($K12,INDIRECT("'"&VLOOKUP($C12,ModMap!$A$2:$B$21,2,FALSE)&"'!$K:$K"),0)),"")} -> N/A | Z12: {=IFERROR(INDEX(INDIRECT("'"&VLOOKUP($C12,ModMap!$A$2:$B$21,2,FALSE)&"'!Z:Z"),MATCH($K12,INDIRECT("'"&VLOOKUP($C12,ModMap!$A$2:$B$21,2,FALSE)&"'!$K:$K"),0)),"")} | AA12: No | AB12: {=IFERROR(INDEX(INDIRECT("'"&VLOOKUP($C12,ModMap!$A$2:$B$21,2,FALSE)&"'!AB:AB"),MATCH($K12,INDIRECT("'"&VLOOKUP($C12,ModMap!$A$2:$B$21,2,FALSE)&"'!$K:$K"),0)),"")} -> N/A | AC12: {=IFERROR(INDEX(INDIRECT("'"&VLOOKUP($C12,ModMap!$A$2:$B$21,2,FALSE)&"'!AC:AC"),MATCH($K12,INDIRECT("'"&VLOOKUP($C12,ModMap!$A$2:$B$21,2,FALSE)&"'!$K:$K"),0)),"")} | AD12: No | AE12: {=IFERROR(INDEX(INDIRECT("'"&VLOOKUP($C12,ModMap!$A$2:$B$21,2,FALSE)&"'!AE:AE"),MATCH($K12,INDIRECT("'"&VLOOKUP($C12,ModMap!$A$2:$B$21,2,FALSE)&"'!$K:$K"),0)),"")} -> N/A | AF12: {=IFERROR(INDEX(INDIRECT("'"&VLOOKUP($C12,ModMap!$A$2:$B$21,2,FALSE)&"'!AF:AF"),MATCH($K12,INDIRECT("'"&VLOOKUP($C12,ModMap!$A$2:$B$21,2,FALSE)&"'!$K:$K"),0)),"")} | AG12: No | AH12: {=IFERROR(INDEX(INDIRECT("'"&VLOOKUP($C12,ModMap!$A$2:$B$21,2,FALSE)&"'!AH:AH"),MATCH($K12,INDIRECT("'"&VLOOKUP($C12,ModMap!$A$2:$B$21,2,FALSE)&"'!$K:$K"),0)),"")} -> N/A | AI12: {=IFERROR(INDEX(INDIRECT("'"&VLOOKUP($C12,ModMap!$A$2:$B$21,2,FALSE)&"'!AI:AI"),MATCH($K12,INDIRECT("'"&VLOOKUP($C12,ModMap!$A$2:$B$21,2,FALSE)&"'!$K:$K"),0)),"")} | AJ12: No | AK12: {=IFERROR(INDEX(INDIRECT("'"&VLOOKUP($C12,ModMap!$A$2:$B$21,2,FALSE)&"'!AK:AK"),MATCH($K12,INDIRECT("'"&VLOOKUP($C12,ModMap!$A$2:$B$21,2,FALSE)&"'!$K:$K"),0)),"")} -> N/A | AL12: {=IFERROR(INDEX(INDIRECT("'"&VLOOKUP($C12,ModMap!$A$2:$B$21,2,FALSE)&"'!AL:AL"),MATCH($K12,INDIRECT("'"&VLOOKUP($C12,ModMap!$A$2:$B$21,2,FALSE)&"'!$K:$K"),0)),"")} | AM12: =IF(AND(U12="Yes",V12<>"Done",V12<>"Deferred",V12<>"N/A"),1,0)+IF(AND(X12="Yes",Y12<>"Done",Y12<>"Deferred",Y12<>"N/A"),1,0)+IF(AND(AA12="Yes",AB12<>"Done",AB12<>"Deferred",AB12<>"N/A"),1,0)+IF(AND(AD12="Yes",AE12<>"Done",AE12<>"Deferred",AE12<>"N/A"),1,0)+IF(AND(AG12="Yes",AH12<>"Done",AH12<>"Deferred",AH12<>"N/A"),1,0)+IF(AND(AJ12="Yes",AK12<>"Done",AK12<>"Deferred",AK12<>"N/A"),1,0) -> 0 | AN12: =IF((IF(U12="Yes",1,0)+IF(X12="Yes",1,0)+IF(AA12="Yes",1,0)+IF(AD12="Yes",1,0)+IF(AG12="Yes",1,0)+IF(AJ12="Yes",1,0))=0,"N/A",IF((IF(AND(U12="Yes",V12="Blocked"),1,0)+IF(AND(X12="Yes",Y12="Blocked"),1,0)+IF(AND(AA12="Yes",AB12="Blocked"),1,0)+IF(AND(AD12="Yes",AE12="Blocked"),1,0)+IF(AND(AG12="Yes",AH12="Blocked"),1,0)+IF(AND(AJ12="Yes",AK12="Blocked"),1,0))>0,"Blocked",IF((IF(AND(U12="Yes",V12="Done"),1,0)+IF(AND(X12="Yes",Y12="Done"),1,0)+IF(AND(AA12="Yes",AB12="Done"),1,0)+IF(AND(AD12="Yes",AE12="Done"),1,0)+IF(AND(AG12="Yes",AH12="Done"),1,0)+IF(AND(AJ12="Yes",AK12="Done"),1,0))=(IF(U12="Yes",1,0)+IF(X12="Yes",1,0)+IF(AA12="Yes",1,0)+IF(AD12="Yes",1,0)+IF(AG12="Yes",1,0)+IF(AJ12="Yes",1,0)),"Done",IF((IF(AND(U12="Yes",OR(V12="In Progress",V12="Done",V12="Deferred")),1,0)+IF(AND(X12="Yes",OR(Y12="In Progress",Y12="Done",Y12="Deferred")),1,0)+IF(AND(AA12="Yes",OR(AB12="In Progress",AB12="Done",AB12="Deferred")),1,0)+IF(AND(AD12="Yes",OR(AE12="In Progress",AE12="Done",AE12="Deferred")),1,0)+IF(AND(AG12="Yes",OR(AH12="In Progress",AH12="Done",AH12="Deferred")),1,0)+IF(AND(AJ12="Yes",OR(AK12="In Progress",AK12="Done",AK12="Deferred")),1,0))>0,"In Progress","Not Started")))) -> N/A | AO12: {=IFERROR(INDEX(INDIRECT("'"&VLOOKUP($C12,ModMap!$A$2:$B$21,2,FALSE)&"'!AO:AO"),MATCH($K12,INDIRECT("'"&VLOOKUP($C12,ModMap!$A$2:$B$21,2,FALSE)&"'!$K:$K"),0)),"")} | AP12: {=IFERROR(HYPERLINK("#'"&VLOOKUP($C12,ModMap!$A$2:$B$21,2,FALSE)&"'!V"&MATCH($K12,INDIRECT("'"&VLOOKUP($C12,ModMap!$A$2:$B$21,2,FALSE)&"'!$K:$K"),0),"Edit on module sheet"),"")} -> Edit on module sheet
